<mujoco model="ur5">
    <actuator>
        <!--velocity name="joint1_velocity" joint="joint1"/>
        <velocity name="joint2_velocity" joint="joint2"/>
        <velocity name="joint3_velocity" joint="joint3"/>
        <velocity name="joint4_velocity" joint="joint4"/>
        <velocity name="joint5_velocity" joint="joint5"/>
        <velocity name="joint6_velocity" joint="joint6"/-->
        <!--velocity name="gripper_velocity" joint="gripper_joint_left" gear="0.04" /-->

        <!--position name="joint1_position" joint="joint1"/>
        <position name="joint2_position" joint="joint2"/>
        <position name="joint3_position" joint="joint3"/>
        <position name="joint4_position" joint="joint4"/>
        <position name="joint5_position" joint="joint5"/>
        <position name="joint6_position" joint="joint6"/-->

        <motor name="joint1_motor" joint="joint1" gear="1.2"/>
        <motor name="joint2_motor" joint="joint2"/>
        <motor name="joint3_motor" joint="joint3"/>
        <motor name="joint4_motor" joint="joint4"/>
        <motor name="joint5_motor" joint="joint5"/>
        <motor name="joint6_motor" joint="joint6"/>
    </actuator>
    <asset>
        <mesh name="base" file="meshes/base.stl" />
        <mesh name="shoulder" file="meshes/shoulder.stl" />
        <mesh name="upperarm" file="meshes/upperarm.stl" />
        <mesh name="forearm" file="meshes/forearm.stl" />
        <mesh name="wrist1" file="meshes/wrist1.stl" />
        <mesh name="wrist2" file="meshes/wrist2.stl" />
        <mesh name="wrist3" file="meshes/wrist3.stl" />

        <material name="RobMat" specular="0.9" shininess="0.5" reflectance="0" rgba="0.7 0.7 0.7 1" emission="0.1" />
    </asset>

    <worldbody>
        <!--geom name="robotiq_85_finger_link_mesh" type="mesh" mesh="robotiq_85_finger_link" pos="0.2 0 1" />
        <geom name="robotiq_85_finger_tip_link_mesh" type="mesh" mesh="robotiq_85_finger_tip_link" pos="0.3 0 1" />
        <geom name="robotiq_85_inner_knuckle_link_mesh" type="mesh" mesh="robotiq_85_inner_knuckle_link" pos="0.4 0 1" />
        <geom name="robotiq_85_knuckle_link_mesh" type="mesh" mesh="robotiq_85_knuckle_link" pos="0.5 0 1" /-->

        <body name="link0" pos="-0.175 0.175 0" quat="0.3826834324 0 0 0.9238795325" >
            <inertial pos="0 0 0" quat="0.5 0.5 -0.5 0.5" mass="4" diaginertia="0.0072 0.00443333 0.00443333" />
            <geom name="link0_collision" type="mesh" mesh="base" material="RobMat" />
            <geom name="base_cap" type="cylinder" pos="0 0 0.14" size="0.06 0.02" rgba="0.596 0.96 1 1" material="RobMat" contype="0" conaffinity="0" />

            <body name="link1" pos="0 0 0.089159">
                <inertial pos="0 0 0" mass="3.7" diaginertia="0.0102675 0.0102675 0.00666" />
                <joint name="joint1" pos="0 0 0" axis="0 0 1" />
                <geom name="link1_collision" type="mesh" mesh="shoulder" material="RobMat" />
                <geom name="shoulder_cap" type="cylinder" pos="0 0.185 0" quat="0.707107 0.707107 0 0" size="0.06 0.02" rgba="0.596 0.96 1 1" material="RobMat" contype="0" conaffinity="0" />
                
                <body name="link2" pos="0 0.13585 0" quat="0.707107 0 0.707107 0">
                    <inertial pos="0 0 0.28" mass="8.393" diaginertia="0.226891 0.226891 0.0151074" />
                    <geom name="link2_collision" type="mesh" mesh="upperarm" material="RobMat" />
                    <joint name="joint2" pos="0 0 0" axis="0 1 0" />

                    <body name="link3" pos="0 -0.1197 0.425">
                        <inertial pos="0 0 0.25" mass="2.275" diaginertia="0.0494433 0.0494433 0.004095" />
                        <geom name="link3_collision" type="mesh" mesh="forearm" material="RobMat" />

                        <!--camera name="forearm_camera" pos="0 0.1 0.07" euler="3.14159265 0 1.570796" /-->

                        <geom name="forearm_cap" type="cylinder" pos="0 0.17 0" quat="0.707107 0.707107 0 0" size="0.06 0.02" rgba="0.596 0.96 1 1" material="RobMat" contype="0" conaffinity="0" />
                        <joint name="joint3" pos="0 0 0" axis="0 1 0" />

                        <body name="link4" pos="0 0 0.39225" quat="0.707107 0 0.707107 0">
                            <inertial pos="0 0 0" quat="0.5 0.5 -0.5 0.5" mass="1.219" diaginertia="0.21942 0.111173 0.111173" />
                            <geom name="link4_collision" type="mesh" mesh="wrist1" material="RobMat" />
                            <geom name="wrist1_cap" type="cylinder" pos="0 -0.045 0" quat="0.707107 0.707107 0 0" size="0.04 0.015" rgba="0.596 0.96 1 1" material="RobMat" contype="0" conaffinity="0" />
                            <joint name="joint4" pos="0 0 0" axis="0 1 0" />

                            <body name="link5" pos="0 0.093 0">
                                <inertial pos="0 0 0" quat="0.5 0.5 -0.5 0.5" mass="1.219" diaginertia="0.21942 0.111173 0.111173" />
                                <geom name="link5_collision" type="mesh" mesh="wrist2" material="RobMat" />
                                <geom name="wrist2_cap" type="cylinder" pos="0 0 -0.045" quat="0.707107 0 0 0.707107" size="0.04 0.015" rgba="0.596 0.96 1 1" material="RobMat" contype="0" conaffinity="0" />
                                <joint name="joint5" pos="0 0 0" axis="0 0 1" />

                                <body name="link6" pos="0 0 0.09465" quat="0.707107 0 -0.707107 0" >
                                    <inertial pos="0 0 0" quat="0.5 0.5 -0.5 0.5" mass="0.1879" diaginertia="0.033822 0.0171365 0.0171365" />
                                    <geom name="link6_collision" type="mesh" mesh="wrist3" material="RobMat" contype="1" conaffinity="1" />
                                    <geom name="wrist3_cap" type="cylinder" pos="0 -0.045 0" quat="0.707107 0.707107 0 0" size="0.04 0.015" rgba="0.596 0.96 1 1" material="RobMat" contype="0" conaffinity="0" />
                                    <joint name="joint6" pos="0 0 0" axis="0 1 0" />

                                    <body name="ee_link" pos="0 0.0823 0" quat="0.707107 -0.707107 0 0">
                                        <!--inertial pos="0 0.0823 0" quat="0.707107 -0.707107 0 0" mass="0" diaginertia="0 0 0" /-->
                                    </body>
                                </body>
                            </body>
                        </body>
                    </body>
                </body>
            </body>
        </body>
    </worldbody>
</mujoco>